<?xml version="1.0"?>

<!-- included by, and macro expanded in, diffbot_urdf.xacro -->

<robot xmlns:xacro="http://www.ros.org/wiki/xacro">

  <xacro:macro name="diffbot" params="prefix">

    <link name="${prefix}base_link"/>

    <joint name="${prefix}left_wheel_joint" type="continuous">
      <parent link="${prefix}base_link"/>
      <child link="${prefix}left_wheel"/>
    </joint>

    <link name="${prefix}left_wheel"/>

    <joint name="${prefix}right_wheel_joint" type="continuous">
      <parent link="${prefix}base_link"/>
      <child link="${prefix}right_wheel"/>
    </joint>

    <link name="${prefix}right_wheel"/>

  </xacro:macro>

</robot>
