<?xml version="1.0"?>

<robot name="diffdrive_robot">

  <link name="base_link">
    <collision>
      <origin xyz="0 0 0" rpy="0 0 0"/>
      <geometry>
        <box size="0.1 0.1 0.05"/>
      </geometry>
    </collision>
  </link>

  <joint name="left_wheel_joint" type="continuous">
    <parent link="base_link"/>
    <child link="left_wheel"/>
    <origin xyz="0 -0.05 -0.025" rpy="0 0 0"/>
    <axis xyz="0 1 0"/>
    <dynamics damping="0.2"/>
    <limit effort="100" velocity="1.0"/>
  </joint>

  <link name="left_wheel">
    <collision>
      <origin xyz="0 0 0" rpy="1.57080 0 0"/>
      <geometry>
        <cylinder length="0.02" radius="0.015"/>
      </geometry>
    </collision>
  </link>

  <joint name="right_wheel_joint" type="continuous">
    <parent link="base_link"/>
    <child link="right_wheel"/>
    <origin xyz="0 0.05 -0.025" rpy="0 0 0"/>
    <axis xyz="0 1 0"/>
    <dynamics damping="0.2"/>
    <limit effort="100" velocity="1.0"/>
  </joint>

  <link name="right_wheel">
    <collision>
      <origin xyz="0 0 0" rpy="1.57080 0 0"/>
      <geometry>
        <cylinder length="0.02" radius="0.015"/>
      </geometry>
    </collision>
  </link>

</robot>
